[I 09:54:45.943 NotebookApp] Writing notebook server cookie secret to /home/jovyan/.local/share/jupyter/runtime/notebook_cookie_secret
[W 2021-09-11 09:54:46.855 LabApp] 'ip' has moved from NotebookApp to ServerApp. This config will be passed to ServerApp. Be sure to update your config before our next release.
[W 2021-09-11 09:54:46.855 LabApp] 'port' has moved from NotebookApp to ServerApp. This config will be passed to ServerApp. Be sure to update your config before our next release.
[W 2021-09-11 09:54:46.855 LabApp] 'base_url' has moved from NotebookApp to ServerApp. This config will be passed to ServerApp. Be sure to update your config before our next release.
[W 2021-09-11 09:54:46.855 LabApp] 'token' has moved from NotebookApp to ServerApp. This config will be passed to ServerApp. Be sure to update your config before our next release.
[W 2021-09-11 09:54:46.855 LabApp] 'trust_xheaders' has moved from NotebookApp to ServerApp. This config will be passed to ServerApp. Be sure to update your config before our next release.
[W 2021-09-11 09:54:46.855 LabApp] 'trust_xheaders' has moved from NotebookApp to ServerApp. This config will be passed to ServerApp. Be sure to update your config before our next release.
[W 2021-09-11 09:54:46.856 LabApp] 'allow_origin' has moved from NotebookApp to ServerApp. This config will be passed to ServerApp. Be sure to update your config before our next release.
[W 2021-09-11 09:54:46.856 LabApp] 'allow_origin_pat' has moved from NotebookApp to ServerApp. This config will be passed to ServerApp. Be sure to update your config before our next release.
[W 2021-09-11 09:54:46.856 LabApp] 'extra_template_paths' was found in both NotebookApp and ServerApp. This is likely a recent change. This config will only be set in NotebookApp. Please check if you should also config these traits in ServerApp for your purpose.
[W 2021-09-11 09:54:46.856 LabApp] 'jinja_template_vars' was found in both NotebookApp and ServerApp. This is likely a recent change. This config will only be set in NotebookApp. Please check if you should also config these traits in ServerApp for your purpose.
[W 2021-09-11 09:54:46.856 LabApp] 'shutdown_no_activity_timeout' has moved from NotebookApp to ServerApp. This config will be passed to ServerApp. Be sure to update your config before our next release.
[W 2021-09-11 09:54:46.856 LabApp] 'tornado_settings' has moved from NotebookApp to ServerApp. This config will be passed to ServerApp. Be sure to update your config before our next release.
[W 2021-09-11 09:54:46.856 LabApp] 'tornado_settings' has moved from NotebookApp to ServerApp. This config will be passed to ServerApp. Be sure to update your config before our next release.
[I 2021-09-11 09:54:46.872 LabApp] JupyterLab extension loaded from /srv/conda/envs/notebook/lib/python3.7/site-packages/jupyterlab
[I 2021-09-11 09:54:46.873 LabApp] JupyterLab application directory is /srv/conda/envs/notebook/share/jupyter/lab
[I 09:54:46.887 NotebookApp] nteract extension loaded from /srv/conda/envs/notebook/lib/python3.7/site-packages/nteract_on_jupyter
[I 09:54:46.890 NotebookApp] Will shut down after 600 seconds with no kernels or terminals.
[I 09:54:46.891 NotebookApp] Serving notebooks from local directory: /home/jovyan
[I 09:54:46.891 NotebookApp] Jupyter Notebook 6.3.0 is running at:
[I 09:54:46.891 NotebookApp] http://jupyter-paulinelvne-2drepresentation-5fde-2ddt38mmx5:8888/user/paulinelvne-representation_de-dt38mmx5/?token=...
[I 09:54:46.891 NotebookApp]  or http://127.0.0.1:8888/user/paulinelvne-representation_de-dt38mmx5/?token=...
[I 09:54:46.891 NotebookApp] Use Control-C to stop this server and shut down all kernels (twice to skip confirmation).
[W 09:54:46.897 NotebookApp] No web browser found: could not locate runnable browser.
[I 09:54:46.900 NotebookApp] 302 GET /user/paulinelvne-representation_de-dt38mmx5/ (10.0.21.16) 1.060000ms
[I 09:54:48.075 NotebookApp] 302 GET /user/paulinelvne-representation_de-dt38mmx5/?token=ZMLCLidjQLitjwPKm0ij4A (78.193.170.244) 0.660000ms
[I 09:54:49.093 NotebookApp] 301 GET /user/paulinelvne-representation_de-dt38mmx5/static/favicons/favicon.ico (78.193.170.244) 0.820000ms
[I 2021-09-11 09:54:54.293 LabApp] Build is up to date
[I 2021-09-11 09:55:32.154 LabApp] Build is up to date
[I 09:55:40.365 NotebookApp] New terminal with automatic name: 1
TermSocket.open: 1
TermSocket.open: Opened 1
[I 09:55:58.901 NotebookApp] Uploading file to /Essai_representation_DE.ipynb
[I 09:56:01.175 NotebookApp] Writing notebook-signing key to /home/jovyan/.local/share/jupyter/notebook_secret
[W 09:56:01.175 NotebookApp] Notebook Essai_representation_DE.ipynb is not trusted
[I 09:56:02.428 NotebookApp] Kernel started: f98e5e91-6e3c-41ee-a3b2-1a25f2dbc945, name: python3
[I 09:56:02.428 NotebookApp] Culling kernels with idle durations > 600 seconds at 60 second intervals ...
[I 09:56:02.428 NotebookApp] Culling kernels even with connected clients
[I 09:56:03.393 NotebookApp] Starting buffering for f98e5e91-6e3c-41ee-a3b2-1a25f2dbc945:a4adbf6a-644c-441a-ace0-994288f0afc4
[I 09:58:01.723 NotebookApp] Saving file at /Essai_representation_DE.ipynb
[E 09:58:01.729 NotebookApp] Error while saving file: Essai_representation_DE.ipynb [Errno 2] No such file or directory: '/srv/conda/envs/notebook/lib/python3.7/site-packages/nbformat/v4/nbformat.v4.4.schema.json'
    Traceback (most recent call last):
      File "/srv/conda/envs/notebook/lib/python3.7/site-packages/notebook/services/contents/filemanager.py", line 477, in save
        self._save_notebook(os_path, nb)
      File "/srv/conda/envs/notebook/lib/python3.7/site-packages/notebook/services/contents/fileio.py", line 291, in _save_notebook
        nbformat.write(nb, f, version=nbformat.NO_CONVERT)
      File "/srv/conda/envs/notebook/lib/python3.7/site-packages/nbformat/__init__.py", line 164, in write
        return write(nb, f, version=version, **kwargs)
      File "/srv/conda/envs/notebook/lib/python3.7/site-packages/nbformat/__init__.py", line 107, in writes
        try:
      File "/srv/conda/envs/notebook/lib/python3.7/site-packages/nbformat/validator.py", line 270, in validate
      File "/srv/conda/envs/notebook/lib/python3.7/site-packages/nbformat/validator.py", line 303, in iter_validate
      File "/srv/conda/envs/notebook/lib/python3.7/site-packages/nbformat/validator.py", line 57, in get_validator
        version = current_nbformat
      File "/srv/conda/envs/notebook/lib/python3.7/site-packages/nbformat/validator.py", line 94, in _get_schema_json
        def _get_schema_json(v):
    FileNotFoundError: [Errno 2] No such file or directory: '/srv/conda/envs/notebook/lib/python3.7/site-packages/nbformat/v4/nbformat.v4.4.schema.json'
[W 09:58:01.732 NotebookApp] 500 PUT /user/paulinelvne-representation_de-dt38mmx5/api/contents/Essai_representation_DE.ipynb?1631354283103 (78.193.170.244): Unexpected error while saving file: Essai_representation_DE.ipynb [Errno 2] No such file or directory: '/srv/conda/envs/notebook/lib/python3.7/site-packages/nbformat/v4/nbformat.v4.4.schema.json'
[W 09:58:01.732 NotebookApp] Unexpected error while saving file: Essai_representation_DE.ipynb [Errno 2] No such file or directory: '/srv/conda/envs/notebook/lib/python3.7/site-packages/nbformat/v4/nbformat.v4.4.schema.json'
[E 09:58:01.733 NotebookApp] {
      "Cookie": "username-hub-gke2-mybinder-org=\"2|1:0|10:1631354281|30:username-hub-gke2-mybinder-org|44:NzZlMWEyNDhjM2U1NDllMGE1NzE3YmFlZTViOTFkMTI=|e4767dab5a50de5aa01d16604528686fe87fbcc4daf84139494a8f2d2051cc12\"; _xsrf=2|e84eadb5|cb4cc8835d2c3f4f3ed959a7e6e865b0|1631354088",
      "Cache-Control": "no-cache",
      "Pragma": "no-cache",
      "Sec-Fetch-Site": "same-origin",
      "Sec-Fetch-Mode": "cors",
      "Sec-Fetch-Dest": "empty",
      "Origin": "https://hub.gke2.mybinder.org",
      "X-Xsrftoken": "2|e84eadb5|cb4cc8835d2c3f4f3ed959a7e6e865b0|1631354088",
      "Authorization": "token ZMLCLidjQLitjwPKm0ij4A",
      "Content-Type": "text/plain;charset=UTF-8",
      "Referer": "https://hub.gke2.mybinder.org/user/paulinelvne-representation_de-dt38mmx5/lab",
      "Accept-Encoding": "gzip, deflate, br",
      "Accept-Language": "fr,fr-FR;q=0.8,en-US;q=0.5,en;q=0.3",
      "Accept": "*/*",
      "User-Agent": "Mozilla/5.0 (Windows NT 10.0; Win64; x64; rv:91.0) Gecko/20100101 Firefox/91.0",
      "Content-Length": "1057",
      "X-Scheme": "https",
      "X-Forwarded-Port": "443,80",
      "X-Forwarded-Host": "hub.gke2.mybinder.org",
      "X-Forwarded-Proto": "https,http",
      "X-Forwarded-For": "78.193.170.244,::ffff:10.0.26.178",
      "X-Real-Ip": "78.193.170.244",
      "X-Request-Id": "e91d6c203f30782f982a4316679fb074",
      "Host": "hub.gke2.mybinder.org",
      "Connection": "close"
    }
[E 09:58:01.733 NotebookApp] 500 PUT /user/paulinelvne-representation_de-dt38mmx5/api/contents/Essai_representation_DE.ipynb?1631354283103 (78.193.170.244) 10.070000ms referer=https://hub.gke2.mybinder.org/user/paulinelvne-representation_de-dt38mmx5/lab
[I 10:00:02.043 NotebookApp] Saving file at /Essai_representation_DE.ipynb
[E 10:00:02.055 NotebookApp] Error while saving file: Essai_representation_DE.ipynb [Errno 2] No such file or directory: '/srv/conda/envs/notebook/lib/python3.7/site-packages/nbformat/v4/nbformat.v4.4.schema.json'
    Traceback (most recent call last):
      File "/srv/conda/envs/notebook/lib/python3.7/site-packages/notebook/services/contents/filemanager.py", line 477, in save
        self._save_notebook(os_path, nb)
      File "/srv/conda/envs/notebook/lib/python3.7/site-packages/notebook/services/contents/fileio.py", line 291, in _save_notebook
        nbformat.write(nb, f, version=nbformat.NO_CONVERT)
      File "/srv/conda/envs/notebook/lib/python3.7/site-packages/nbformat/__init__.py", line 164, in write
        return write(nb, f, version=version, **kwargs)
      File "/srv/conda/envs/notebook/lib/python3.7/site-packages/nbformat/__init__.py", line 107, in writes
        try:
      File "/srv/conda/envs/notebook/lib/python3.7/site-packages/nbformat/validator.py", line 270, in validate
      File "/srv/conda/envs/notebook/lib/python3.7/site-packages/nbformat/validator.py", line 303, in iter_validate
      File "/srv/conda/envs/notebook/lib/python3.7/site-packages/nbformat/validator.py", line 57, in get_validator
        version = current_nbformat
      File "/srv/conda/envs/notebook/lib/python3.7/site-packages/nbformat/validator.py", line 94, in _get_schema_json
        def _get_schema_json(v):
    FileNotFoundError: [Errno 2] No such file or directory: '/srv/conda/envs/notebook/lib/python3.7/site-packages/nbformat/v4/nbformat.v4.4.schema.json'
[W 10:00:02.055 NotebookApp] 500 PUT /user/paulinelvne-representation_de-dt38mmx5/api/contents/Essai_representation_DE.ipynb?1631354403447 (78.193.170.244): Unexpected error while saving file: Essai_representation_DE.ipynb [Errno 2] No such file or directory: '/srv/conda/envs/notebook/lib/python3.7/site-packages/nbformat/v4/nbformat.v4.4.schema.json'
[W 10:00:02.056 NotebookApp] Unexpected error while saving file: Essai_representation_DE.ipynb [Errno 2] No such file or directory: '/srv/conda/envs/notebook/lib/python3.7/site-packages/nbformat/v4/nbformat.v4.4.schema.json'
[E 10:00:02.056 NotebookApp] {
      "Cookie": "username-hub-gke2-mybinder-org=\"2|1:0|10:1631354401|30:username-hub-gke2-mybinder-org|44:MGI1Y2MxZTNjMTdlNDJiYTkyYWQyZGNlM2Q1OGQwOWU=|b335c90a7623df305c0937a7b22cf6c8692da1ce386c3c04a0ece7716452888c\"; _xsrf=2|e84eadb5|cb4cc8835d2c3f4f3ed959a7e6e865b0|1631354088",
      "Cache-Control": "no-cache",
      "Pragma": "no-cache",
      "Sec-Fetch-Site": "same-origin",
      "Sec-Fetch-Mode": "cors",
      "Sec-Fetch-Dest": "empty",
      "Origin": "https://hub.gke2.mybinder.org",
      "X-Xsrftoken": "2|e84eadb5|cb4cc8835d2c3f4f3ed959a7e6e865b0|1631354088",
      "Authorization": "token ZMLCLidjQLitjwPKm0ij4A",
      "Content-Type": "text/plain;charset=UTF-8",
      "Referer": "https://hub.gke2.mybinder.org/user/paulinelvne-representation_de-dt38mmx5/lab",
      "Accept-Encoding": "gzip, deflate, br",
      "Accept-Language": "fr,fr-FR;q=0.8,en-US;q=0.5,en;q=0.3",
      "Accept": "*/*",
      "User-Agent": "Mozilla/5.0 (Windows NT 10.0; Win64; x64; rv:91.0) Gecko/20100101 Firefox/91.0",
      "Content-Length": "1057",
      "X-Scheme": "https",
      "X-Forwarded-Port": "443,80",
      "X-Forwarded-Host": "hub.gke2.mybinder.org",
      "X-Forwarded-Proto": "https,http",
      "X-Forwarded-For": "78.193.170.244,::ffff:10.0.26.178",
      "X-Real-Ip": "78.193.170.244",
      "X-Request-Id": "e844b0a6e78417ff99660bf2e499f819",
      "Host": "hub.gke2.mybinder.org",
      "Connection": "close"
    }
[E 10:00:02.056 NotebookApp] 500 PUT /user/paulinelvne-representation_de-dt38mmx5/api/contents/Essai_representation_DE.ipynb?1631354403447 (78.193.170.244) 14.570000ms referer=https://hub.gke2.mybinder.org/user/paulinelvne-representation_de-dt38mmx5/lab
[I 10:02:03.060 NotebookApp] Saving file at /Essai_representation_DE.ipynb
[E 10:02:03.070 NotebookApp] Error while saving file: Essai_representation_DE.ipynb [Errno 2] No such file or directory: '/srv/conda/envs/notebook/lib/python3.7/site-packages/nbformat/v4/nbformat.v4.4.schema.json'
    Traceback (most recent call last):
      File "/srv/conda/envs/notebook/lib/python3.7/site-packages/notebook/services/contents/filemanager.py", line 477, in save
        self._save_notebook(os_path, nb)
      File "/srv/conda/envs/notebook/lib/python3.7/site-packages/notebook/services/contents/fileio.py", line 291, in _save_notebook
        nbformat.write(nb, f, version=nbformat.NO_CONVERT)
      File "/srv/conda/envs/notebook/lib/python3.7/site-packages/nbformat/__init__.py", line 164, in write
        return write(nb, f, version=version, **kwargs)
      File "/srv/conda/envs/notebook/lib/python3.7/site-packages/nbformat/__init__.py", line 107, in writes
        try:
      File "/srv/conda/envs/notebook/lib/python3.7/site-packages/nbformat/validator.py", line 270, in validate
      File "/srv/conda/envs/notebook/lib/python3.7/site-packages/nbformat/validator.py", line 303, in iter_validate
      File "/srv/conda/envs/notebook/lib/python3.7/site-packages/nbformat/validator.py", line 57, in get_validator
        version = current_nbformat
      File "/srv/conda/envs/notebook/lib/python3.7/site-packages/nbformat/validator.py", line 94, in _get_schema_json
        def _get_schema_json(v):
    FileNotFoundError: [Errno 2] No such file or directory: '/srv/conda/envs/notebook/lib/python3.7/site-packages/nbformat/v4/nbformat.v4.4.schema.json'
[W 10:02:03.070 NotebookApp] 500 PUT /user/paulinelvne-representation_de-dt38mmx5/api/contents/Essai_representation_DE.ipynb?1631354524424 (78.193.170.244): Unexpected error while saving file: Essai_representation_DE.ipynb [Errno 2] No such file or directory: '/srv/conda/envs/notebook/lib/python3.7/site-packages/nbformat/v4/nbformat.v4.4.schema.json'
[W 10:02:03.071 NotebookApp] Unexpected error while saving file: Essai_representation_DE.ipynb [Errno 2] No such file or directory: '/srv/conda/envs/notebook/lib/python3.7/site-packages/nbformat/v4/nbformat.v4.4.schema.json'
[E 10:02:03.071 NotebookApp] {
      "Cookie": "username-hub-gke2-mybinder-org=\"2|1:0|10:1631354522|30:username-hub-gke2-mybinder-org|44:ODhkOTc2NzVhNDhjNDQ4OTg1ZjA0NDE0MzJiOTI2ZTE=|fac901d48c08c45dd730ee4bbe0b1b3b83fd1ee71b5927050b2485e94f5a7dff\"; _xsrf=2|e84eadb5|cb4cc8835d2c3f4f3ed959a7e6e865b0|1631354088",
      "Cache-Control": "no-cache",
      "Pragma": "no-cache",
      "Sec-Fetch-Site": "same-origin",
      "Sec-Fetch-Mode": "cors",
      "Sec-Fetch-Dest": "empty",
      "Origin": "https://hub.gke2.mybinder.org",
      "X-Xsrftoken": "2|e84eadb5|cb4cc8835d2c3f4f3ed959a7e6e865b0|1631354088",
      "Authorization": "token ZMLCLidjQLitjwPKm0ij4A",
      "Content-Type": "text/plain;charset=UTF-8",
      "Referer": "https://hub.gke2.mybinder.org/user/paulinelvne-representation_de-dt38mmx5/lab",
      "Accept-Encoding": "gzip, deflate, br",
      "Accept-Language": "fr,fr-FR;q=0.8,en-US;q=0.5,en;q=0.3",
      "Accept": "*/*",
      "User-Agent": "Mozilla/5.0 (Windows NT 10.0; Win64; x64; rv:91.0) Gecko/20100101 Firefox/91.0",
      "Content-Length": "1057",
      "X-Scheme": "https",
      "X-Forwarded-Port": "443,80",
      "X-Forwarded-Host": "hub.gke2.mybinder.org",
      "X-Forwarded-Proto": "https,http",
      "X-Forwarded-For": "78.193.170.244,::ffff:10.0.26.178",
      "X-Real-Ip": "78.193.170.244",
      "X-Request-Id": "c6a6998bb2c7a0d5f051ec0c1a16ca31",
      "Host": "hub.gke2.mybinder.org",
      "Connection": "close"
    }
[E 10:02:03.072 NotebookApp] 500 PUT /user/paulinelvne-representation_de-dt38mmx5/api/contents/Essai_representation_DE.ipynb?1631354524424 (78.193.170.244) 12.140000ms referer=https://hub.gke2.mybinder.org/user/paulinelvne-representation_de-dt38mmx5/lab
[I 10:02:36.096 NotebookApp] Saving file at /Essai_representation_DE.ipynb
[E 10:02:36.106 NotebookApp] Error while saving file: Essai_representation_DE.ipynb [Errno 2] No such file or directory: '/srv/conda/envs/notebook/lib/python3.7/site-packages/nbformat/v4/nbformat.v4.4.schema.json'
    Traceback (most recent call last):
      File "/srv/conda/envs/notebook/lib/python3.7/site-packages/notebook/services/contents/filemanager.py", line 477, in save
        self._save_notebook(os_path, nb)
      File "/srv/conda/envs/notebook/lib/python3.7/site-packages/notebook/services/contents/fileio.py", line 291, in _save_notebook
        nbformat.write(nb, f, version=nbformat.NO_CONVERT)
      File "/srv/conda/envs/notebook/lib/python3.7/site-packages/nbformat/__init__.py", line 164, in write
        return write(nb, f, version=version, **kwargs)
      File "/srv/conda/envs/notebook/lib/python3.7/site-packages/nbformat/__init__.py", line 107, in writes
        try:
      File "/srv/conda/envs/notebook/lib/python3.7/site-packages/nbformat/validator.py", line 270, in validate
      File "/srv/conda/envs/notebook/lib/python3.7/site-packages/nbformat/validator.py", line 303, in iter_validate
      File "/srv/conda/envs/notebook/lib/python3.7/site-packages/nbformat/validator.py", line 57, in get_validator
        version = current_nbformat
      File "/srv/conda/envs/notebook/lib/python3.7/site-packages/nbformat/validator.py", line 94, in _get_schema_json
        def _get_schema_json(v):
    FileNotFoundError: [Errno 2] No such file or directory: '/srv/conda/envs/notebook/lib/python3.7/site-packages/nbformat/v4/nbformat.v4.4.schema.json'
[W 10:02:36.106 NotebookApp] 500 PUT /user/paulinelvne-representation_de-dt38mmx5/api/contents/Essai_representation_DE.ipynb?1631354557461 (78.193.170.244): Unexpected error while saving file: Essai_representation_DE.ipynb [Errno 2] No such file or directory: '/srv/conda/envs/notebook/lib/python3.7/site-packages/nbformat/v4/nbformat.v4.4.schema.json'
[W 10:02:36.106 NotebookApp] Unexpected error while saving file: Essai_representation_DE.ipynb [Errno 2] No such file or directory: '/srv/conda/envs/notebook/lib/python3.7/site-packages/nbformat/v4/nbformat.v4.4.schema.json'
[E 10:02:36.107 NotebookApp] {
      "Cookie": "username-hub-gke2-mybinder-org=\"2|1:0|10:1631354555|30:username-hub-gke2-mybinder-org|44:YzEyOTZmNWJlNDU3NGZjZGEyZWYzMzgxMDkwOGYwNzg=|ebc5d7824268c58e2ad1773237f99bc5d3469689d5d85310f56019566a894646\"; _xsrf=2|e84eadb5|cb4cc8835d2c3f4f3ed959a7e6e865b0|1631354088",
      "Cache-Control": "no-cache",
      "Pragma": "no-cache",
      "Sec-Fetch-Site": "same-origin",
      "Sec-Fetch-Mode": "cors",
      "Sec-Fetch-Dest": "empty",
      "Origin": "https://hub.gke2.mybinder.org",
      "X-Xsrftoken": "2|e84eadb5|cb4cc8835d2c3f4f3ed959a7e6e865b0|1631354088",
      "Authorization": "token ZMLCLidjQLitjwPKm0ij4A",
      "Content-Type": "text/plain;charset=UTF-8",
      "Referer": "https://hub.gke2.mybinder.org/user/paulinelvne-representation_de-dt38mmx5/lab/tree/Essai_representation_DE.ipynb",
      "Accept-Encoding": "gzip, deflate, br",
      "Accept-Language": "fr,fr-FR;q=0.8,en-US;q=0.5,en;q=0.3",
      "Accept": "*/*",
      "User-Agent": "Mozilla/5.0 (Windows NT 10.0; Win64; x64; rv:91.0) Gecko/20100101 Firefox/91.0",
      "Content-Length": "1057",
      "X-Scheme": "https",
      "X-Forwarded-Port": "443,80",
      "X-Forwarded-Host": "hub.gke2.mybinder.org",
      "X-Forwarded-Proto": "https,http",
      "X-Forwarded-For": "78.193.170.244,::ffff:10.0.26.178",
      "X-Real-Ip": "78.193.170.244",
      "X-Request-Id": "bdf1bb1735b24a73d1566ab3a45c1f7e",
      "Host": "hub.gke2.mybinder.org",
      "Connection": "close"
    }
[E 10:02:36.107 NotebookApp] 500 PUT /user/paulinelvne-representation_de-dt38mmx5/api/contents/Essai_representation_DE.ipynb?1631354557461 (78.193.170.244) 12.140000ms referer=https://hub.gke2.mybinder.org/user/paulinelvne-representation_de-dt38mmx5/lab/tree/Essai_representation_DE.ipynb
[I 10:04:03.031 NotebookApp] Saving file at /Essai_representation_DE.ipynb
[E 10:04:03.042 NotebookApp] Error while saving file: Essai_representation_DE.ipynb [Errno 2] No such file or directory: '/srv/conda/envs/notebook/lib/python3.7/site-packages/nbformat/v4/nbformat.v4.4.schema.json'
    Traceback (most recent call last):
      File "/srv/conda/envs/notebook/lib/python3.7/site-packages/notebook/services/contents/filemanager.py", line 477, in save
        self._save_notebook(os_path, nb)
      File "/srv/conda/envs/notebook/lib/python3.7/site-packages/notebook/services/contents/fileio.py", line 291, in _save_notebook
        nbformat.write(nb, f, version=nbformat.NO_CONVERT)
      File "/srv/conda/envs/notebook/lib/python3.7/site-packages/nbformat/__init__.py", line 164, in write
        return write(nb, f, version=version, **kwargs)
      File "/srv/conda/envs/notebook/lib/python3.7/site-packages/nbformat/__init__.py", line 107, in writes
        try:
      File "/srv/conda/envs/notebook/lib/python3.7/site-packages/nbformat/validator.py", line 270, in validate
      File "/srv/conda/envs/notebook/lib/python3.7/site-packages/nbformat/validator.py", line 303, in iter_validate
      File "/srv/conda/envs/notebook/lib/python3.7/site-packages/nbformat/validator.py", line 57, in get_validator
        version = current_nbformat
      File "/srv/conda/envs/notebook/lib/python3.7/site-packages/nbformat/validator.py", line 94, in _get_schema_json
        def _get_schema_json(v):
    FileNotFoundError: [Errno 2] No such file or directory: '/srv/conda/envs/notebook/lib/python3.7/site-packages/nbformat/v4/nbformat.v4.4.schema.json'
[W 10:04:03.042 NotebookApp] 500 PUT /user/paulinelvne-representation_de-dt38mmx5/api/contents/Essai_representation_DE.ipynb?1631354644414 (78.193.170.244): Unexpected error while saving file: Essai_representation_DE.ipynb [Errno 2] No such file or directory: '/srv/conda/envs/notebook/lib/python3.7/site-packages/nbformat/v4/nbformat.v4.4.schema.json'
[W 10:04:03.042 NotebookApp] Unexpected error while saving file: Essai_representation_DE.ipynb [Errno 2] No such file or directory: '/srv/conda/envs/notebook/lib/python3.7/site-packages/nbformat/v4/nbformat.v4.4.schema.json'
[E 10:04:03.043 NotebookApp] {
      "Cookie": "username-hub-gke2-mybinder-org=\"2|1:0|10:1631354642|30:username-hub-gke2-mybinder-org|44:NTEzZDY2MmJmMmNkNGIyZWEzMDE4NmMwYmEyZWEzZjk=|3cbfbbf46cb5533e83b217b24652a9a1f5316d0b951cb8abd3c9edc97faf106c\"; _xsrf=2|e84eadb5|cb4cc8835d2c3f4f3ed959a7e6e865b0|1631354088",
      "Cache-Control": "no-cache",
      "Pragma": "no-cache",
      "Sec-Fetch-Site": "same-origin",
      "Sec-Fetch-Mode": "cors",
      "Sec-Fetch-Dest": "empty",
      "Origin": "https://hub.gke2.mybinder.org",
      "X-Xsrftoken": "2|e84eadb5|cb4cc8835d2c3f4f3ed959a7e6e865b0|1631354088",
      "Authorization": "token ZMLCLidjQLitjwPKm0ij4A",
      "Content-Type": "text/plain;charset=UTF-8",
      "Referer": "https://hub.gke2.mybinder.org/user/paulinelvne-representation_de-dt38mmx5/lab/tree/Essai_representation_DE.ipynb",
      "Accept-Encoding": "gzip, deflate, br",
      "Accept-Language": "fr,fr-FR;q=0.8,en-US;q=0.5,en;q=0.3",
      "Accept": "*/*",
      "User-Agent": "Mozilla/5.0 (Windows NT 10.0; Win64; x64; rv:91.0) Gecko/20100101 Firefox/91.0",
      "Content-Length": "1057",
      "X-Scheme": "https",
      "X-Forwarded-Port": "443,80",
      "X-Forwarded-Host": "hub.gke2.mybinder.org",
      "X-Forwarded-Proto": "https,http",
      "X-Forwarded-For": "78.193.170.244,::ffff:10.0.26.178",
      "X-Real-Ip": "78.193.170.244",
      "X-Request-Id": "ed634a0731b11e41e1099166a9322e56",
      "Host": "hub.gke2.mybinder.org",
      "Connection": "close"
    }
[E 10:04:03.043 NotebookApp] 500 PUT /user/paulinelvne-representation_de-dt38mmx5/api/contents/Essai_representation_DE.ipynb?1631354644414 (78.193.170.244) 13.060000ms referer=https://hub.gke2.mybinder.org/user/paulinelvne-representation_de-dt38mmx5/lab/tree/Essai_representation_DE.ipynb
[I 10:06:03.360 NotebookApp] Saving file at /Essai_representation_DE.ipynb
[E 10:06:03.369 NotebookApp] Error while saving file: Essai_representation_DE.ipynb [Errno 2] No such file or directory: '/srv/conda/envs/notebook/lib/python3.7/site-packages/nbformat/v4/nbformat.v4.4.schema.json'
    Traceback (most recent call last):
      File "/srv/conda/envs/notebook/lib/python3.7/site-packages/notebook/services/contents/filemanager.py", line 477, in save
        self._save_notebook(os_path, nb)
      File "/srv/conda/envs/notebook/lib/python3.7/site-packages/notebook/services/contents/fileio.py", line 291, in _save_notebook
        nbformat.write(nb, f, version=nbformat.NO_CONVERT)
      File "/srv/conda/envs/notebook/lib/python3.7/site-packages/nbformat/__init__.py", line 164, in write
        return write(nb, f, version=version, **kwargs)
      File "/srv/conda/envs/notebook/lib/python3.7/site-packages/nbformat/__init__.py", line 107, in writes
        try:
      File "/srv/conda/envs/notebook/lib/python3.7/site-packages/nbformat/validator.py", line 270, in validate
      File "/srv/conda/envs/notebook/lib/python3.7/site-packages/nbformat/validator.py", line 303, in iter_validate
      File "/srv/conda/envs/notebook/lib/python3.7/site-packages/nbformat/validator.py", line 57, in get_validator
        version = current_nbformat
      File "/srv/conda/envs/notebook/lib/python3.7/site-packages/nbformat/validator.py", line 94, in _get_schema_json
        def _get_schema_json(v):
    FileNotFoundError: [Errno 2] No such file or directory: '/srv/conda/envs/notebook/lib/python3.7/site-packages/nbformat/v4/nbformat.v4.4.schema.json'
[W 10:06:03.370 NotebookApp] 500 PUT /user/paulinelvne-representation_de-dt38mmx5/api/contents/Essai_representation_DE.ipynb?1631354764708 (78.193.170.244): Unexpected error while saving file: Essai_representation_DE.ipynb [Errno 2] No such file or directory: '/srv/conda/envs/notebook/lib/python3.7/site-packages/nbformat/v4/nbformat.v4.4.schema.json'
[W 10:06:03.370 NotebookApp] Unexpected error while saving file: Essai_representation_DE.ipynb [Errno 2] No such file or directory: '/srv/conda/envs/notebook/lib/python3.7/site-packages/nbformat/v4/nbformat.v4.4.schema.json'
[E 10:06:03.372 NotebookApp] {
      "Cookie": "username-hub-gke2-mybinder-org=\"2|1:0|10:1631354763|30:username-hub-gke2-mybinder-org|44:ODNkOTdlMTQ4ZTQxNDAxYjgzNjY1MWE3ODZkZTJhZjY=|a6ff8c705c2907fee3c9fac9b5ccc40c091af89d382b465f47b41df77136bc37\"; _xsrf=2|e84eadb5|cb4cc8835d2c3f4f3ed959a7e6e865b0|1631354088",
      "Cache-Control": "no-cache",
      "Pragma": "no-cache",
      "Sec-Fetch-Site": "same-origin",
      "Sec-Fetch-Mode": "cors",
      "Sec-Fetch-Dest": "empty",
      "Origin": "https://hub.gke2.mybinder.org",
      "X-Xsrftoken": "2|e84eadb5|cb4cc8835d2c3f4f3ed959a7e6e865b0|1631354088",
      "Authorization": "token ZMLCLidjQLitjwPKm0ij4A",
      "Content-Type": "text/plain;charset=UTF-8",
      "Referer": "https://hub.gke2.mybinder.org/user/paulinelvne-representation_de-dt38mmx5/lab",
      "Accept-Encoding": "gzip, deflate, br",
      "Accept-Language": "fr,fr-FR;q=0.8,en-US;q=0.5,en;q=0.3",
      "Accept": "*/*",
      "User-Agent": "Mozilla/5.0 (Windows NT 10.0; Win64; x64; rv:91.0) Gecko/20100101 Firefox/91.0",
      "Content-Length": "1057",
      "X-Scheme": "https",
      "X-Forwarded-Port": "443,80",
      "X-Forwarded-Host": "hub.gke2.mybinder.org",
      "X-Forwarded-Proto": "https,http",
      "X-Forwarded-For": "78.193.170.244,::ffff:10.0.26.178",
      "X-Real-Ip": "78.193.170.244",
      "X-Request-Id": "13a92feeff87e5bc8fef3145b3b41b21",
      "Host": "hub.gke2.mybinder.org",
      "Connection": "close"
    }
[E 10:06:03.372 NotebookApp] 500 PUT /user/paulinelvne-representation_de-dt38mmx5/api/contents/Essai_representation_DE.ipynb?1631354764708 (78.193.170.244) 13.050000ms referer=https://hub.gke2.mybinder.org/user/paulinelvne-representation_de-dt38mmx5/lab
[W 10:07:02.429 NotebookApp] Culling 'idle' kernel 'python3' (f98e5e91-6e3c-41ee-a3b2-1a25f2dbc945) with 2 connections due to 658 seconds of inactivity.
[I 10:07:02.429 NotebookApp] Kernel shutdown: f98e5e91-6e3c-41ee-a3b2-1a25f2dbc945
[I 10:08:03.349 NotebookApp] Saving file at /Essai_representation_DE.ipynb
[E 10:08:03.360 NotebookApp] Error while saving file: Essai_representation_DE.ipynb [Errno 2] No such file or directory: '/srv/conda/envs/notebook/lib/python3.7/site-packages/nbformat/v4/nbformat.v4.4.schema.json'
    Traceback (most recent call last):
      File "/srv/conda/envs/notebook/lib/python3.7/site-packages/notebook/services/contents/filemanager.py", line 477, in save
        self._save_notebook(os_path, nb)
      File "/srv/conda/envs/notebook/lib/python3.7/site-packages/notebook/services/contents/fileio.py", line 291, in _save_notebook
        nbformat.write(nb, f, version=nbformat.NO_CONVERT)
      File "/srv/conda/envs/notebook/lib/python3.7/site-packages/nbformat/__init__.py", line 164, in write
        return write(nb, f, version=version, **kwargs)
      File "/srv/conda/envs/notebook/lib/python3.7/site-packages/nbformat/__init__.py", line 107, in writes
        try:
      File "/srv/conda/envs/notebook/lib/python3.7/site-packages/nbformat/validator.py", line 270, in validate
      File "/srv/conda/envs/notebook/lib/python3.7/site-packages/nbformat/validator.py", line 303, in iter_validate
      File "/srv/conda/envs/notebook/lib/python3.7/site-packages/nbformat/validator.py", line 57, in get_validator
        version = current_nbformat
      File "/srv/conda/envs/notebook/lib/python3.7/site-packages/nbformat/validator.py", line 94, in _get_schema_json
        def _get_schema_json(v):
    FileNotFoundError: [Errno 2] No such file or directory: '/srv/conda/envs/notebook/lib/python3.7/site-packages/nbformat/v4/nbformat.v4.4.schema.json'
[W 10:08:03.360 NotebookApp] 500 PUT /user/paulinelvne-representation_de-dt38mmx5/api/contents/Essai_representation_DE.ipynb?1631354884726 (78.193.170.244): Unexpected error while saving file: Essai_representation_DE.ipynb [Errno 2] No such file or directory: '/srv/conda/envs/notebook/lib/python3.7/site-packages/nbformat/v4/nbformat.v4.4.schema.json'
[W 10:08:03.360 NotebookApp] Unexpected error while saving file: Essai_representation_DE.ipynb [Errno 2] No such file or directory: '/srv/conda/envs/notebook/lib/python3.7/site-packages/nbformat/v4/nbformat.v4.4.schema.json'
[E 10:08:03.361 NotebookApp] {
      "Cookie": "username-hub-gke2-mybinder-org=\"2|1:0|10:1631354883|30:username-hub-gke2-mybinder-org|44:OWU2NjQ3ZjI3Y2YyNGI3MmI0ZGZmNzk0ZmJmNDhlYmY=|af99148f365d441cd940fd3bb229345d75df2e62830d415e7f2111e77f15f8eb\"; _xsrf=2|e84eadb5|cb4cc8835d2c3f4f3ed959a7e6e865b0|1631354088",
      "Cache-Control": "no-cache",
      "Pragma": "no-cache",
      "Sec-Fetch-Site": "same-origin",
      "Sec-Fetch-Mode": "cors",
      "Sec-Fetch-Dest": "empty",
      "Origin": "https://hub.gke2.mybinder.org",
      "X-Xsrftoken": "2|e84eadb5|cb4cc8835d2c3f4f3ed959a7e6e865b0|1631354088",
      "Authorization": "token ZMLCLidjQLitjwPKm0ij4A",
      "Content-Type": "text/plain;charset=UTF-8",
      "Referer": "https://hub.gke2.mybinder.org/user/paulinelvne-representation_de-dt38mmx5/lab",
      "Accept-Encoding": "gzip, deflate, br",
      "Accept-Language": "fr,fr-FR;q=0.8,en-US;q=0.5,en;q=0.3",
      "Accept": "*/*",
      "User-Agent": "Mozilla/5.0 (Windows NT 10.0; Win64; x64; rv:91.0) Gecko/20100101 Firefox/91.0",
      "Content-Length": "1057",
      "X-Scheme": "https",
      "X-Forwarded-Port": "443,80",
      "X-Forwarded-Host": "hub.gke2.mybinder.org",
      "X-Forwarded-Proto": "https,http",
      "X-Forwarded-For": "78.193.170.244,::ffff:10.0.26.178",
      "X-Real-Ip": "78.193.170.244",
      "X-Request-Id": "1971d6e6a254b26813db90de4eb9d8b7",
      "Host": "hub.gke2.mybinder.org",
      "Connection": "close"
    }
[E 10:08:03.361 NotebookApp] 500 PUT /user/paulinelvne-representation_de-dt38mmx5/api/contents/Essai_representation_DE.ipynb?1631354884726 (78.193.170.244) 12.810000ms referer=https://hub.gke2.mybinder.org/user/paulinelvne-representation_de-dt38mmx5/lab
[I 10:10:03.300 NotebookApp] Saving file at /Essai_representation_DE.ipynb
[E 10:10:03.309 NotebookApp] Error while saving file: Essai_representation_DE.ipynb [Errno 2] No such file or directory: '/srv/conda/envs/notebook/lib/python3.7/site-packages/nbformat/v4/nbformat.v4.4.schema.json'
    Traceback (most recent call last):
      File "/srv/conda/envs/notebook/lib/python3.7/site-packages/notebook/services/contents/filemanager.py", line 477, in save
        self._save_notebook(os_path, nb)
      File "/srv/conda/envs/notebook/lib/python3.7/site-packages/notebook/services/contents/fileio.py", line 291, in _save_notebook
        nbformat.write(nb, f, version=nbformat.NO_CONVERT)
      File "/srv/conda/envs/notebook/lib/python3.7/site-packages/nbformat/__init__.py", line 164, in write
        return write(nb, f, version=version, **kwargs)
      File "/srv/conda/envs/notebook/lib/python3.7/site-packages/nbformat/__init__.py", line 107, in writes
        try:
      File "/srv/conda/envs/notebook/lib/python3.7/site-packages/nbformat/validator.py", line 270, in validate
      File "/srv/conda/envs/notebook/lib/python3.7/site-packages/nbformat/validator.py", line 303, in iter_validate
      File "/srv/conda/envs/notebook/lib/python3.7/site-packages/nbformat/validator.py", line 57, in get_validator
        version = current_nbformat
      File "/srv/conda/envs/notebook/lib/python3.7/site-packages/nbformat/validator.py", line 94, in _get_schema_json
        def _get_schema_json(v):
    FileNotFoundError: [Errno 2] No such file or directory: '/srv/conda/envs/notebook/lib/python3.7/site-packages/nbformat/v4/nbformat.v4.4.schema.json'
[W 10:10:03.309 NotebookApp] 500 PUT /user/paulinelvne-representation_de-dt38mmx5/api/contents/Essai_representation_DE.ipynb?1631355004703 (78.193.170.244): Unexpected error while saving file: Essai_representation_DE.ipynb [Errno 2] No such file or directory: '/srv/conda/envs/notebook/lib/python3.7/site-packages/nbformat/v4/nbformat.v4.4.schema.json'
[W 10:10:03.310 NotebookApp] Unexpected error while saving file: Essai_representation_DE.ipynb [Errno 2] No such file or directory: '/srv/conda/envs/notebook/lib/python3.7/site-packages/nbformat/v4/nbformat.v4.4.schema.json'
[E 10:10:03.310 NotebookApp] {
      "Cookie": "username-hub-gke2-mybinder-org=\"2|1:0|10:1631355003|30:username-hub-gke2-mybinder-org|44:MThkYjJlZmEyYmNkNDVmM2E2OTZlZjc0NTBlOTVkMDE=|89a6c123ff3537e96dcd838228b99b3ac33b6fdaa1b9da40f1242f4d2bee88c8\"; _xsrf=2|e84eadb5|cb4cc8835d2c3f4f3ed959a7e6e865b0|1631354088",
      "Cache-Control": "no-cache",
      "Pragma": "no-cache",
      "Sec-Fetch-Site": "same-origin",
      "Sec-Fetch-Mode": "cors",
      "Sec-Fetch-Dest": "empty",
      "Origin": "https://hub.gke2.mybinder.org",
      "X-Xsrftoken": "2|e84eadb5|cb4cc8835d2c3f4f3ed959a7e6e865b0|1631354088",
      "Authorization": "token ZMLCLidjQLitjwPKm0ij4A",
      "Content-Type": "text/plain;charset=UTF-8",
      "Referer": "https://hub.gke2.mybinder.org/user/paulinelvne-representation_de-dt38mmx5/lab",
      "Accept-Encoding": "gzip, deflate, br",
      "Accept-Language": "fr,fr-FR;q=0.8,en-US;q=0.5,en;q=0.3",
      "Accept": "*/*",
      "User-Agent": "Mozilla/5.0 (Windows NT 10.0; Win64; x64; rv:91.0) Gecko/20100101 Firefox/91.0",
      "Content-Length": "1057",
      "X-Scheme": "https",
      "X-Forwarded-Port": "443,80",
      "X-Forwarded-Host": "hub.gke2.mybinder.org",
      "X-Forwarded-Proto": "https,http",
      "X-Forwarded-For": "78.193.170.244,::ffff:10.0.26.178",
      "X-Real-Ip": "78.193.170.244",
      "X-Request-Id": "62237d8b0cbc2351a9181b99089dfcd0",
      "Host": "hub.gke2.mybinder.org",
      "Connection": "close"
    }
[E 10:10:03.310 NotebookApp] 500 PUT /user/paulinelvne-representation_de-dt38mmx5/api/contents/Essai_representation_DE.ipynb?1631355004703 (78.193.170.244) 11.160000ms referer=https://hub.gke2.mybinder.org/user/paulinelvne-representation_de-dt38mmx5/lab
[I 10:12:03.363 NotebookApp] Saving file at /Essai_representation_DE.ipynb
[E 10:12:03.374 NotebookApp] Error while saving file: Essai_representation_DE.ipynb [Errno 2] No such file or directory: '/srv/conda/envs/notebook/lib/python3.7/site-packages/nbformat/v4/nbformat.v4.4.schema.json'
    Traceback (most recent call last):
      File "/srv/conda/envs/notebook/lib/python3.7/site-packages/notebook/services/contents/filemanager.py", line 477, in save
        self._save_notebook(os_path, nb)
      File "/srv/conda/envs/notebook/lib/python3.7/site-packages/notebook/services/contents/fileio.py", line 291, in _save_notebook
        nbformat.write(nb, f, version=nbformat.NO_CONVERT)
      File "/srv/conda/envs/notebook/lib/python3.7/site-packages/nbformat/__init__.py", line 164, in write
        return write(nb, f, version=version, **kwargs)
      File "/srv/conda/envs/notebook/lib/python3.7/site-packages/nbformat/__init__.py", line 107, in writes
        try:
      File "/srv/conda/envs/notebook/lib/python3.7/site-packages/nbformat/validator.py", line 270, in validate
      File "/srv/conda/envs/notebook/lib/python3.7/site-packages/nbformat/validator.py", line 303, in iter_validate
      File "/srv/conda/envs/notebook/lib/python3.7/site-packages/nbformat/validator.py", line 57, in get_validator
        version = current_nbformat
      File "/srv/conda/envs/notebook/lib/python3.7/site-packages/nbformat/validator.py", line 94, in _get_schema_json
        def _get_schema_json(v):
    FileNotFoundError: [Errno 2] No such file or directory: '/srv/conda/envs/notebook/lib/python3.7/site-packages/nbformat/v4/nbformat.v4.4.schema.json'
[W 10:12:03.374 NotebookApp] 500 PUT /user/paulinelvne-representation_de-dt38mmx5/api/contents/Essai_representation_DE.ipynb?1631355124748 (78.193.170.244): Unexpected error while saving file: Essai_representation_DE.ipynb [Errno 2] No such file or directory: '/srv/conda/envs/notebook/lib/python3.7/site-packages/nbformat/v4/nbformat.v4.4.schema.json'
[W 10:12:03.374 NotebookApp] Unexpected error while saving file: Essai_representation_DE.ipynb [Errno 2] No such file or directory: '/srv/conda/envs/notebook/lib/python3.7/site-packages/nbformat/v4/nbformat.v4.4.schema.json'
[E 10:12:03.375 NotebookApp] {
      "Cookie": "username-hub-gke2-mybinder-org=\"2|1:0|10:1631355123|30:username-hub-gke2-mybinder-org|44:NTNiM2ViMWE4MDY0NDM2OWE5NWIyYWE2Y2Q1NTg5NWQ=|4f89282f60e9f4b230a9bfc171936b159d78ee1c3e91d50bcee59171f5c484b9\"; _xsrf=2|e84eadb5|cb4cc8835d2c3f4f3ed959a7e6e865b0|1631354088",
      "Cache-Control": "no-cache",
      "Pragma": "no-cache",
      "Sec-Fetch-Site": "same-origin",
      "Sec-Fetch-Mode": "cors",
      "Sec-Fetch-Dest": "empty",
      "Origin": "https://hub.gke2.mybinder.org",
      "X-Xsrftoken": "2|e84eadb5|cb4cc8835d2c3f4f3ed959a7e6e865b0|1631354088",
      "Authorization": "token ZMLCLidjQLitjwPKm0ij4A",
      "Content-Type": "text/plain;charset=UTF-8",
      "Referer": "https://hub.gke2.mybinder.org/user/paulinelvne-representation_de-dt38mmx5/lab/tree/Essai_representation_DE.ipynb",
      "Accept-Encoding": "gzip, deflate, br",
      "Accept-Language": "fr,fr-FR;q=0.8,en-US;q=0.5,en;q=0.3",
      "Accept": "*/*",
      "User-Agent": "Mozilla/5.0 (Windows NT 10.0; Win64; x64; rv:91.0) Gecko/20100101 Firefox/91.0",
      "Content-Length": "952",
      "X-Scheme": "https",
      "X-Forwarded-Port": "443,80",
      "X-Forwarded-Host": "hub.gke2.mybinder.org",
      "X-Forwarded-Proto": "https,http",
      "X-Forwarded-For": "78.193.170.244,::ffff:10.0.26.178",
      "X-Real-Ip": "78.193.170.244",
      "X-Request-Id": "2ad573ddb1a4f0d51276d70647d06622",
      "Host": "hub.gke2.mybinder.org",
      "Connection": "close"
    }
[E 10:12:03.375 NotebookApp] 500 PUT /user/paulinelvne-representation_de-dt38mmx5/api/contents/Essai_representation_DE.ipynb?1631355124748 (78.193.170.244) 13.460000ms referer=https://hub.gke2.mybinder.org/user/paulinelvne-representation_de-dt38mmx5/lab/tree/Essai_representation_DE.ipynb
[I 10:14:03.471 NotebookApp] Saving file at /Essai_representation_DE.ipynb
[E 10:14:03.478 NotebookApp] Error while saving file: Essai_representation_DE.ipynb [Errno 2] No such file or directory: '/srv/conda/envs/notebook/lib/python3.7/site-packages/nbformat/v4/nbformat.v4.4.schema.json'
    Traceback (most recent call last):
      File "/srv/conda/envs/notebook/lib/python3.7/site-packages/notebook/services/contents/filemanager.py", line 477, in save
        self._save_notebook(os_path, nb)
      File "/srv/conda/envs/notebook/lib/python3.7/site-packages/notebook/services/contents/fileio.py", line 291, in _save_notebook
        nbformat.write(nb, f, version=nbformat.NO_CONVERT)
      File "/srv/conda/envs/notebook/lib/python3.7/site-packages/nbformat/__init__.py", line 164, in write
        return write(nb, f, version=version, **kwargs)
      File "/srv/conda/envs/notebook/lib/python3.7/site-packages/nbformat/__init__.py", line 107, in writes
        try:
      File "/srv/conda/envs/notebook/lib/python3.7/site-packages/nbformat/validator.py", line 270, in validate
      File "/srv/conda/envs/notebook/lib/python3.7/site-packages/nbformat/validator.py", line 303, in iter_validate
      File "/srv/conda/envs/notebook/lib/python3.7/site-packages/nbformat/validator.py", line 57, in get_validator
        version = current_nbformat
      File "/srv/conda/envs/notebook/lib/python3.7/site-packages/nbformat/validator.py", line 94, in _get_schema_json
        def _get_schema_json(v):
    FileNotFoundError: [Errno 2] No such file or directory: '/srv/conda/envs/notebook/lib/python3.7/site-packages/nbformat/v4/nbformat.v4.4.schema.json'
[W 10:14:03.478 NotebookApp] 500 PUT /user/paulinelvne-representation_de-dt38mmx5/api/contents/Essai_representation_DE.ipynb?1631355244867 (78.193.170.244): Unexpected error while saving file: Essai_representation_DE.ipynb [Errno 2] No such file or directory: '/srv/conda/envs/notebook/lib/python3.7/site-packages/nbformat/v4/nbformat.v4.4.schema.json'
[W 10:14:03.479 NotebookApp] Unexpected error while saving file: Essai_representation_DE.ipynb [Errno 2] No such file or directory: '/srv/conda/envs/notebook/lib/python3.7/site-packages/nbformat/v4/nbformat.v4.4.schema.json'
[E 10:14:03.479 NotebookApp] {
      "Cookie": "username-hub-gke2-mybinder-org=\"2|1:0|10:1631355243|30:username-hub-gke2-mybinder-org|44:ODdmZjU0ZTBhN2UzNDJiNmE0YjYyNjcwYzA2YzljYmU=|76e0820fabd383bd722dc6fb30ca370f1e7750fb2ac52c151bf728de6d06f537\"; _xsrf=2|e84eadb5|cb4cc8835d2c3f4f3ed959a7e6e865b0|1631354088",
      "Cache-Control": "no-cache",
      "Pragma": "no-cache",
      "Sec-Fetch-Site": "same-origin",
      "Sec-Fetch-Mode": "cors",
      "Sec-Fetch-Dest": "empty",
      "Origin": "https://hub.gke2.mybinder.org",
      "X-Xsrftoken": "2|e84eadb5|cb4cc8835d2c3f4f3ed959a7e6e865b0|1631354088",
      "Authorization": "token ZMLCLidjQLitjwPKm0ij4A",
      "Content-Type": "text/plain;charset=UTF-8",
      "Referer": "https://hub.gke2.mybinder.org/user/paulinelvne-representation_de-dt38mmx5/lab/tree/Essai_representation_DE.ipynb",
      "Accept-Encoding": "gzip, deflate, br",
      "Accept-Language": "fr,fr-FR;q=0.8,en-US;q=0.5,en;q=0.3",
      "Accept": "*/*",
      "User-Agent": "Mozilla/5.0 (Windows NT 10.0; Win64; x64; rv:91.0) Gecko/20100101 Firefox/91.0",
      "Content-Length": "1501",
      "X-Scheme": "https",
      "X-Forwarded-Port": "443,80",
      "X-Forwarded-Host": "hub.gke2.mybinder.org",
      "X-Forwarded-Proto": "https,http",
      "X-Forwarded-For": "78.193.170.244,::ffff:10.0.26.178",
      "X-Real-Ip": "78.193.170.244",
      "X-Request-Id": "00ac41a88c87405a120b0162a1fcf12e",
      "Host": "hub.gke2.mybinder.org",
      "Connection": "close"
    }
[E 10:14:03.480 NotebookApp] 500 PUT /user/paulinelvne-representation_de-dt38mmx5/api/contents/Essai_representation_DE.ipynb?1631355244867 (78.193.170.244) 9.610000ms referer=https://hub.gke2.mybinder.org/user/paulinelvne-representation_de-dt38mmx5/lab/tree/Essai_representation_DE.ipynb
[I 10:16:03.520 NotebookApp] Saving file at /Essai_representation_DE.ipynb
[E 10:16:03.555 NotebookApp] Error while saving file: Essai_representation_DE.ipynb [Errno 2] No such file or directory: '/srv/conda/envs/notebook/lib/python3.7/site-packages/nbformat/v4/nbformat.v4.4.schema.json'
    Traceback (most recent call last):
      File "/srv/conda/envs/notebook/lib/python3.7/site-packages/notebook/services/contents/filemanager.py", line 477, in save
        self._save_notebook(os_path, nb)
      File "/srv/conda/envs/notebook/lib/python3.7/site-packages/notebook/services/contents/fileio.py", line 291, in _save_notebook
        nbformat.write(nb, f, version=nbformat.NO_CONVERT)
      File "/srv/conda/envs/notebook/lib/python3.7/site-packages/nbformat/__init__.py", line 164, in write
        return write(nb, f, version=version, **kwargs)
      File "/srv/conda/envs/notebook/lib/python3.7/site-packages/nbformat/__init__.py", line 107, in writes
        try:
      File "/srv/conda/envs/notebook/lib/python3.7/site-packages/nbformat/validator.py", line 270, in validate
      File "/srv/conda/envs/notebook/lib/python3.7/site-packages/nbformat/validator.py", line 303, in iter_validate
      File "/srv/conda/envs/notebook/lib/python3.7/site-packages/nbformat/validator.py", line 57, in get_validator
        version = current_nbformat
      File "/srv/conda/envs/notebook/lib/python3.7/site-packages/nbformat/validator.py", line 94, in _get_schema_json
        def _get_schema_json(v):
    FileNotFoundError: [Errno 2] No such file or directory: '/srv/conda/envs/notebook/lib/python3.7/site-packages/nbformat/v4/nbformat.v4.4.schema.json'
[W 10:16:03.555 NotebookApp] 500 PUT /user/paulinelvne-representation_de-dt38mmx5/api/contents/Essai_representation_DE.ipynb?1631355364911 (78.193.170.244): Unexpected error while saving file: Essai_representation_DE.ipynb [Errno 2] No such file or directory: '/srv/conda/envs/notebook/lib/python3.7/site-packages/nbformat/v4/nbformat.v4.4.schema.json'
[W 10:16:03.556 NotebookApp] Unexpected error while saving file: Essai_representation_DE.ipynb [Errno 2] No such file or directory: '/srv/conda/envs/notebook/lib/python3.7/site-packages/nbformat/v4/nbformat.v4.4.schema.json'
[E 10:16:03.557 NotebookApp] {
      "Cookie": "username-hub-gke2-mybinder-org=\"2|1:0|10:1631355363|30:username-hub-gke2-mybinder-org|44:YTcyNDFhYjAyYjViNGIzMDhiM2Q2NjBiODVkZGM0MTU=|8a1b41dd0b0c548a287ee66a97df19f0edc2f5751ad411a7441b50c8e9626efe\"; _xsrf=2|e84eadb5|cb4cc8835d2c3f4f3ed959a7e6e865b0|1631354088",
      "Cache-Control": "no-cache",
      "Pragma": "no-cache",
      "Sec-Fetch-Site": "same-origin",
      "Sec-Fetch-Mode": "cors",
      "Sec-Fetch-Dest": "empty",
      "Origin": "https://hub.gke2.mybinder.org",
      "X-Xsrftoken": "2|e84eadb5|cb4cc8835d2c3f4f3ed959a7e6e865b0|1631354088",
      "Authorization": "token ZMLCLidjQLitjwPKm0ij4A",
      "Content-Type": "text/plain;charset=UTF-8",
      "Referer": "https://hub.gke2.mybinder.org/user/paulinelvne-representation_de-dt38mmx5/lab/tree/Essai_representation_DE.ipynb",
      "Accept-Encoding": "gzip, deflate, br",
      "Accept-Language": "fr,fr-FR;q=0.8,en-US;q=0.5,en;q=0.3",
      "Accept": "*/*",
      "User-Agent": "Mozilla/5.0 (Windows NT 10.0; Win64; x64; rv:91.0) Gecko/20100101 Firefox/91.0",
      "Content-Length": "1727",
      "X-Scheme": "https",
      "X-Forwarded-Port": "443,80",
      "X-Forwarded-Host": "hub.gke2.mybinder.org",
      "X-Forwarded-Proto": "https,http",
      "X-Forwarded-For": "78.193.170.244,::ffff:10.0.26.178",
      "X-Real-Ip": "78.193.170.244",
      "X-Request-Id": "693cc9366648c75e1ae8bb861a295bfe",
      "Host": "hub.gke2.mybinder.org",
      "Connection": "close"
    }
[E 10:16:03.557 NotebookApp] 500 PUT /user/paulinelvne-representation_de-dt38mmx5/api/contents/Essai_representation_DE.ipynb?1631355364911 (78.193.170.244) 38.550000ms referer=https://hub.gke2.mybinder.org/user/paulinelvne-representation_de-dt38mmx5/lab/tree/Essai_representation_DE.ipynb
[I 10:16:22.111 NotebookApp] Saving file at /Essai_representation_DE.ipynb
[E 10:16:22.119 NotebookApp] Error while saving file: Essai_representation_DE.ipynb [Errno 2] No such file or directory: '/srv/conda/envs/notebook/lib/python3.7/site-packages/nbformat/v4/nbformat.v4.4.schema.json'
    Traceback (most recent call last):
      File "/srv/conda/envs/notebook/lib/python3.7/site-packages/notebook/services/contents/filemanager.py", line 477, in save
        self._save_notebook(os_path, nb)
      File "/srv/conda/envs/notebook/lib/python3.7/site-packages/notebook/services/contents/fileio.py", line 291, in _save_notebook
        nbformat.write(nb, f, version=nbformat.NO_CONVERT)
      File "/srv/conda/envs/notebook/lib/python3.7/site-packages/nbformat/__init__.py", line 164, in write
        return write(nb, f, version=version, **kwargs)
      File "/srv/conda/envs/notebook/lib/python3.7/site-packages/nbformat/__init__.py", line 107, in writes
        try:
      File "/srv/conda/envs/notebook/lib/python3.7/site-packages/nbformat/validator.py", line 270, in validate
      File "/srv/conda/envs/notebook/lib/python3.7/site-packages/nbformat/validator.py", line 303, in iter_validate
      File "/srv/conda/envs/notebook/lib/python3.7/site-packages/nbformat/validator.py", line 57, in get_validator
        version = current_nbformat
      File "/srv/conda/envs/notebook/lib/python3.7/site-packages/nbformat/validator.py", line 94, in _get_schema_json
        def _get_schema_json(v):
    FileNotFoundError: [Errno 2] No such file or directory: '/srv/conda/envs/notebook/lib/python3.7/site-packages/nbformat/v4/nbformat.v4.4.schema.json'
[W 10:16:22.119 NotebookApp] 500 PUT /user/paulinelvne-representation_de-dt38mmx5/api/contents/Essai_representation_DE.ipynb?1631355383504 (78.193.170.244): Unexpected error while saving file: Essai_representation_DE.ipynb [Errno 2] No such file or directory: '/srv/conda/envs/notebook/lib/python3.7/site-packages/nbformat/v4/nbformat.v4.4.schema.json'
[W 10:16:22.120 NotebookApp] Unexpected error while saving file: Essai_representation_DE.ipynb [Errno 2] No such file or directory: '/srv/conda/envs/notebook/lib/python3.7/site-packages/nbformat/v4/nbformat.v4.4.schema.json'
[E 10:16:22.121 NotebookApp] {
      "Cookie": "username-hub-gke2-mybinder-org=\"2|1:0|10:1631355381|30:username-hub-gke2-mybinder-org|44:ODIxMTI0NDZhNDkzNDUyY2JjNTY3ZDNmYTY4NGExOWY=|9bc5e874c294f7f6d8ee2d3d9763560c89ac7b217883c4a2721853e6fb6c0084\"; _xsrf=2|e84eadb5|cb4cc8835d2c3f4f3ed959a7e6e865b0|1631354088",
      "Cache-Control": "no-cache",
      "Pragma": "no-cache",
      "Sec-Fetch-Site": "same-origin",
      "Sec-Fetch-Mode": "cors",
      "Sec-Fetch-Dest": "empty",
      "Origin": "https://hub.gke2.mybinder.org",
      "X-Xsrftoken": "2|e84eadb5|cb4cc8835d2c3f4f3ed959a7e6e865b0|1631354088",
      "Authorization": "token ZMLCLidjQLitjwPKm0ij4A",
      "Content-Type": "text/plain;charset=UTF-8",
      "Referer": "https://hub.gke2.mybinder.org/user/paulinelvne-representation_de-dt38mmx5/lab/tree/Essai_representation_DE.ipynb",
      "Accept-Encoding": "gzip, deflate, br",
      "Accept-Language": "fr,fr-FR;q=0.8,en-US;q=0.5,en;q=0.3",
      "Accept": "*/*",
      "User-Agent": "Mozilla/5.0 (Windows NT 10.0; Win64; x64; rv:91.0) Gecko/20100101 Firefox/91.0",
      "Content-Length": "1695",
      "X-Scheme": "https",
      "X-Forwarded-Port": "443,80",
      "X-Forwarded-Host": "hub.gke2.mybinder.org",
      "X-Forwarded-Proto": "https,http",
      "X-Forwarded-For": "78.193.170.244,::ffff:10.0.26.178",
      "X-Real-Ip": "78.193.170.244",
      "X-Request-Id": "00e3aed1733a004fec0f1ceee80260a3",
      "Host": "hub.gke2.mybinder.org",
      "Connection": "close"
    }
[E 10:16:22.121 NotebookApp] 500 PUT /user/paulinelvne-representation_de-dt38mmx5/api/contents/Essai_representation_DE.ipynb?1631355383504 (78.193.170.244) 10.810000ms referer=https://hub.gke2.mybinder.org/user/paulinelvne-representation_de-dt38mmx5/lab/tree/Essai_representation_DE.ipynb
[I 10:16:36.600 NotebookApp] Saving file at /Essai_representation_DE.ipynb
[E 10:16:36.610 NotebookApp] Error while saving file: Essai_representation_DE.ipynb [Errno 2] No such file or directory: '/srv/conda/envs/notebook/lib/python3.7/site-packages/nbformat/v4/nbformat.v4.4.schema.json'
    Traceback (most recent call last):
      File "/srv/conda/envs/notebook/lib/python3.7/site-packages/notebook/services/contents/filemanager.py", line 477, in save
        self._save_notebook(os_path, nb)
      File "/srv/conda/envs/notebook/lib/python3.7/site-packages/notebook/services/contents/fileio.py", line 291, in _save_notebook
        nbformat.write(nb, f, version=nbformat.NO_CONVERT)
      File "/srv/conda/envs/notebook/lib/python3.7/site-packages/nbformat/__init__.py", line 164, in write
        return write(nb, f, version=version, **kwargs)
      File "/srv/conda/envs/notebook/lib/python3.7/site-packages/nbformat/__init__.py", line 107, in writes
        try:
      File "/srv/conda/envs/notebook/lib/python3.7/site-packages/nbformat/validator.py", line 270, in validate
      File "/srv/conda/envs/notebook/lib/python3.7/site-packages/nbformat/validator.py", line 303, in iter_validate
      File "/srv/conda/envs/notebook/lib/python3.7/site-packages/nbformat/validator.py", line 57, in get_validator
        version = current_nbformat
      File "/srv/conda/envs/notebook/lib/python3.7/site-packages/nbformat/validator.py", line 94, in _get_schema_json
        def _get_schema_json(v):
    FileNotFoundError: [Errno 2] No such file or directory: '/srv/conda/envs/notebook/lib/python3.7/site-packages/nbformat/v4/nbformat.v4.4.schema.json'
[W 10:16:36.611 NotebookApp] 500 PUT /user/paulinelvne-representation_de-dt38mmx5/api/contents/Essai_representation_DE.ipynb?1631355397993 (78.193.170.244): Unexpected error while saving file: Essai_representation_DE.ipynb [Errno 2] No such file or directory: '/srv/conda/envs/notebook/lib/python3.7/site-packages/nbformat/v4/nbformat.v4.4.schema.json'
[W 10:16:36.611 NotebookApp] Unexpected error while saving file: Essai_representation_DE.ipynb [Errno 2] No such file or directory: '/srv/conda/envs/notebook/lib/python3.7/site-packages/nbformat/v4/nbformat.v4.4.schema.json'
[E 10:16:36.611 NotebookApp] {
      "Cookie": "username-hub-gke2-mybinder-org=\"2|1:0|10:1631355396|30:username-hub-gke2-mybinder-org|44:NWRhYjY3NGQ5YzQ5NDYzY2I4ZDc3OTdjNzhmODExYWM=|c7b2fa79e9fd07f68603bf23513d8cf7bf40c4987fae2898f642160b58261d89\"; _xsrf=2|e84eadb5|cb4cc8835d2c3f4f3ed959a7e6e865b0|1631354088",
      "Cache-Control": "no-cache",
      "Pragma": "no-cache",
      "Sec-Fetch-Site": "same-origin",
      "Sec-Fetch-Mode": "cors",
      "Sec-Fetch-Dest": "empty",
      "Origin": "https://hub.gke2.mybinder.org",
      "X-Xsrftoken": "2|e84eadb5|cb4cc8835d2c3f4f3ed959a7e6e865b0|1631354088",
      "Authorization": "token ZMLCLidjQLitjwPKm0ij4A",
      "Content-Type": "text/plain;charset=UTF-8",
      "Referer": "https://hub.gke2.mybinder.org/user/paulinelvne-representation_de-dt38mmx5/lab/tree/Essai_representation_DE.ipynb",
      "Accept-Encoding": "gzip, deflate, br",
      "Accept-Language": "fr,fr-FR;q=0.8,en-US;q=0.5,en;q=0.3",
      "Accept": "*/*",
      "User-Agent": "Mozilla/5.0 (Windows NT 10.0; Win64; x64; rv:91.0) Gecko/20100101 Firefox/91.0",
      "Content-Length": "1695",
      "X-Scheme": "https",
      "X-Forwarded-Port": "443,80",
      "X-Forwarded-Host": "hub.gke2.mybinder.org",
      "X-Forwarded-Proto": "https,http",
      "X-Forwarded-For": "78.193.170.244,::ffff:10.0.26.178",
      "X-Real-Ip": "78.193.170.244",
      "X-Request-Id": "b66c5c67ca2fb7650303c2c3d582ff0e",
      "Host": "hub.gke2.mybinder.org",
      "Connection": "close"
    }
[E 10:16:36.612 NotebookApp] 500 PUT /user/paulinelvne-representation_de-dt38mmx5/api/contents/Essai_representation_DE.ipynb?1631355397993 (78.193.170.244) 12.380000ms referer=https://hub.gke2.mybinder.org/user/paulinelvne-representation_de-dt38mmx5/lab/tree/Essai_representation_DE.ipynb
